<mujoco model="stiff-rope">
<!-- Texture Assets -->
    <asset>
        <texture type="skybox" builtin="gradient" rgb1="0.3 0.5 0.7" rgb2="0 0 0" width="512" height="3072"/>
        <texture type="2d" name="groundplane" builtin="checker" mark="edge" rgb1="0.2 0.3 0.4" rgb2="0.1 0.2 0.3"
                    markrgb="0.8 0.8 0.8" width="300" height="300"/>
        <material name="groundplane" texture="groundplane" texuniform="true" texrepeat="5 5" reflectance="0.2"/>

    </asset>
  <compiler angle="radian" />

  <extension>
    <plugin plugin="mujoco.elasticity.cable">
      <instance name="composite">
        <config key="twist" value="859195.0347674177" />
        <config key="bend" value="1175438.4977980438" />
        <config key="twist_displace" value="0.0" />
      </instance>
    </plugin>
  </extension>

  <custom>
    <text name="composite_" data="wire_" />
  </custom>

  <worldbody>
    <body name="stiffrope" pos="0.25 0 0.5" quat="0 0 1 0">
      <joint name="freejoint_A" type="free" limited="false" actuatorfrclimited="false" />
      <body name="B_first">
        <geom name="G0" size="0.006 0.00833333" pos="0.00833333 0 0" quat="0.707107 0 -0.707107 0" type="capsule" contype="0" conaffinity="0" condim="1" solref="0.001" mass="0.000441834" rgba="0.1 0.0533333 0.673333 1" />
        <site name="S_first" pos="0 0 0" group="3" />
        <plugin instance="composite" />
        <body name="B_1" pos="0.0166667 0 0">
          <joint name="J_1" pos="0 0 0" type="ball" group="3" actuatorfrclimited="false" damping="0.1" />
          <geom name="G1" size="0.006 0.00833333" pos="0.00833333 0 0" quat="0.707107 0 -0.707107 0" type="capsule" contype="0" conaffinity="0" condim="1" solref="0.001" mass="0.000441834" rgba="0.1 0.0533333 0.673333 1" />
          <plugin instance="composite" />
          <body name="B_2" pos="0.0166667 0 0">
            <joint name="J_2" pos="0 0 0" type="ball" group="3" actuatorfrclimited="false" damping="0.1" />
            <geom name="G2" size="0.006 0.00833333" pos="0.00833333 0 0" quat="0.707107 0 -0.707107 0" type="capsule" contype="0" conaffinity="0" condim="1" solref="0.001" mass="0.000441834" rgba="0.1 0.0533333 0.673333 1" />
            <plugin instance="composite" />
            <body name="B_3" pos="0.0166667 0 0">
              <joint name="J_3" pos="0 0 0" type="ball" group="3" actuatorfrclimited="false" damping="0.1" />
              <geom name="G3" size="0.006 0.00833333" pos="0.00833333 0 0" quat="0.707107 0 -0.707107 0" type="capsule" contype="0" conaffinity="0" condim="1" solref="0.001" mass="0.000441834" rgba="0.1 0.0533333 0.673333 1" />
              <plugin instance="composite" />
              <body name="B_4" pos="0.0166667 0 0">
                <joint name="J_4" pos="0 0 0" type="ball" group="3" actuatorfrclimited="false" damping="0.1" />
                <geom name="G4" size="0.006 0.00833333" pos="0.00833333 0 0" quat="0.707107 0 -0.707107 0" type="capsule" contype="0" conaffinity="0" condim="1" solref="0.001" mass="0.000441834" rgba="0.1 0.0533333 0.673333 1" />
                <plugin instance="composite" />
                <body name="B_5" pos="0.0166667 0 0">
                  <joint name="J_5" pos="0 0 0" type="ball" group="3" actuatorfrclimited="false" damping="0.1" />
                  <geom name="G5" size="0.006 0.00833333" pos="0.00833333 0 0" quat="0.707107 0 -0.707107 0" type="capsule" contype="0" conaffinity="0" condim="1" solref="0.001" mass="0.000441834" rgba="0.1 0.0533333 0.673333 1" />
                  <plugin instance="composite" />
                  <body name="B_6" pos="0.0166667 0 0">
                    <joint name="J_6" pos="0 0 0" type="ball" group="3" actuatorfrclimited="false" damping="0.1" />
                    <geom name="G6" size="0.006 0.00833333" pos="0.00833333 0 0" quat="0.707107 0 -0.707107 0" type="capsule" contype="0" conaffinity="0" condim="1" solref="0.001" mass="0.000441834" rgba="0.1 0.0533333 0.673333 1" />
                    <plugin instance="composite" />
                    <body name="B_7" pos="0.0166667 0 0">
                      <joint name="J_7" pos="0 0 0" type="ball" group="3" actuatorfrclimited="false" damping="0.1" />
                      <geom name="G7" size="0.006 0.00833334" pos="0.00833334 0 0" quat="0.707107 0 -0.707107 0" type="capsule" contype="0" conaffinity="0" condim="1" solref="0.001" mass="0.000441834" rgba="0.1 0.0533333 0.673333 1" />
                      <plugin instance="composite" />
                      <body name="B_8" pos="0.0166667 0 0">
                        <site name="S_8" pos="1 0 0" group="3"/>
<joint name="J_8" pos="0 0 0" type="ball" group="3" actuatorfrclimited="false" damping="0.1" />
                        <geom name="G8" size="0.006 0.00833333" pos="0.00833333 0 0" quat="0.707107 0 -0.707107 0" type="capsule" contype="0" conaffinity="0" condim="1" solref="0.001" mass="0.000441834" rgba="0.1 0.0533333 0.673333 1" />
                        <plugin instance="composite" />
                        <body name="B_9" pos="0.0166667 0 0">
                          <joint name="J_9" pos="0 0 0" type="ball" group="3" actuatorfrclimited="false" damping="0.1" />
                          <geom name="G9" size="0.006 0.00833333" pos="0.00833333 0 0" quat="0.707107 0 -0.707107 0" type="capsule" contype="0" conaffinity="0" condim="1" solref="0.001" mass="0.000441834" rgba="0.1 0.0533333 0.673333 1" />
                          <plugin instance="composite" />
                          <body name="B_10" pos="0.0166667 0 0">
                            <site name="S_10" pos="1 0 0" group="3" />
<joint name="J_10" pos="0 0 0" type="ball" group="3" actuatorfrclimited="false" damping="0.1" />
                            <geom name="G10" size="0.006 0.00833333" pos="0.00833333 0 0" quat="0.707107 0 -0.707107 0" type="capsule" contype="0" conaffinity="0" condim="1" solref="0.001" mass="0.000441834" rgba="0.1 0.0533333 0.673333 1" />
                            <plugin instance="composite" />
                            <body name="B_11" pos="0.0166667 0 0">
                              <joint name="J_11" pos="0 0 0" type="ball" group="3" actuatorfrclimited="false" damping="0.1" />
                              <geom name="G11" size="0.006 0.00833333" pos="0.00833333 0 0" quat="0.707107 0 -0.707107 0" type="capsule" contype="0" conaffinity="0" condim="1" solref="0.001" mass="0.000441834" rgba="0.1 0.0533333 0.673333 1" />
                              <plugin instance="composite" />
                              <body name="B_12" pos="0.0166667 0 0">
                                <joint name="J_12" pos="0 0 0" type="ball" group="3" actuatorfrclimited="false" damping="0.1" />
                                <geom name="G12" size="0.006 0.00833333" pos="0.00833333 0 0" quat="0.707107 0 -0.707107 0" type="capsule" contype="0" conaffinity="0" condim="1" solref="0.001" mass="0.000441834" rgba="0.1 0.0533333 0.673333 1" />
                                <plugin instance="composite" />
                                <body name="B_13" pos="0.0166667 0 0">
                                  <joint name="J_13" pos="0 0 0" type="ball" group="3" actuatorfrclimited="false" damping="0.1" />
                                  <geom name="G13" size="0.006 0.00833333" pos="0.00833333 0 0" quat="0.707107 0 -0.707107 0" type="capsule" contype="0" conaffinity="0" condim="1" solref="0.001" mass="0.000441834" rgba="0.1 0.0533333 0.673333 1" />
                                  <plugin instance="composite" />
                                  <body name="B_14" pos="0.0166667 0 0">
                                    <joint name="J_14" pos="0 0 0" type="ball" group="3" actuatorfrclimited="false" damping="0.1" />
                                    <geom name="G14" size="0.006 0.00833333" pos="0.00833333 0 0" quat="0.707107 0 -0.707107 0" type="capsule" contype="0" conaffinity="0" condim="1" solref="0.001" mass="0.000441834" rgba="0.1 0.0533333 0.673333 1" />
                                    <plugin instance="composite" />
                                    <body name="B_15" pos="0.0166667 0 0">
                                      <joint name="J_15" pos="0 0 0" type="ball" group="3" actuatorfrclimited="false" damping="0.1" />
                                      <geom name="G15" size="0.006 0.00833334" pos="0.00833334 0 0" quat="0.707107 0 -0.707107 0" type="capsule" contype="0" conaffinity="0" condim="1" solref="0.001" mass="0.000441834" rgba="0.1 0.0533333 0.673333 1" />
                                      <plugin instance="composite" />
                                      <body name="B_16" pos="0.0166667 0 0">
                                        <joint name="J_16" pos="0 0 0" type="ball" group="3" actuatorfrclimited="false" damping="0.1" />
                                        <geom name="G16" size="0.006 0.00833333" pos="0.00833333 0 0" quat="0.707107 0 -0.707107 0" type="capsule" contype="0" conaffinity="0" condim="1" solref="0.001" mass="0.000441834" rgba="0.1 0.0533333 0.673333 1" />
                                        <plugin instance="composite" />
                                        <body name="B_17" pos="0.0166667 0 0">
                                          <joint name="J_17" pos="0 0 0" type="ball" group="3" actuatorfrclimited="false" damping="0.1" />
                                          <geom name="G17" size="0.006 0.00833334" pos="0.00833334 0 0" quat="0.707107 0 -0.707107 0" type="capsule" contype="0" conaffinity="0" condim="1" solref="0.001" mass="0.000441834" rgba="0.1 0.0533333 0.673333 1" />
                                          <plugin instance="composite" />
                                          <body name="B_18" pos="0.0166667 0 0">
                                            <joint name="J_18" pos="0 0 0" type="ball" group="3" actuatorfrclimited="false" damping="0.1" />
                                            <geom name="G18" size="0.006 0.00833333" pos="0.00833333 0 0" quat="0.707107 0 -0.707107 0" type="capsule" contype="0" conaffinity="0" condim="1" solref="0.001" mass="0.000441834" rgba="0.1 0.0533333 0.673333 1" />
                                            <plugin instance="composite" />
                                            <body name="B_19" pos="0.0166667 0 0">
                                              <joint name="J_19" pos="0 0 0" type="ball" group="3" actuatorfrclimited="false" damping="0.1" />
                                              <geom name="G19" size="0.006 0.00833334" pos="0.00833334 0 0" quat="0.707107 0 -0.707107 0" type="capsule" contype="0" conaffinity="0" condim="1" solref="0.001" mass="0.000441834" rgba="0.1 0.0533333 0.673333 1" />
                                              <plugin instance="composite" />
                                              <body name="B_20" pos="0.0166667 0 0">
                                                <joint name="J_20" pos="0 0 0" type="ball" group="3" actuatorfrclimited="false" damping="0.1" />
                                                <geom name="G20" size="0.006 0.00833333" pos="0.00833333 0 0" quat="0.707107 0 -0.707107 0" type="capsule" contype="0" conaffinity="0" condim="1" solref="0.001" mass="0.000441834" rgba="0.1 0.0533333 0.673333 1" />
                                                <plugin instance="composite" />
                                                <body name="B_21" pos="0.0166667 0 0">
                                                  <joint name="J_21" pos="0 0 0" type="ball" group="3" actuatorfrclimited="false" damping="0.1" />
                                                  <geom name="G21" size="0.006 0.00833334" pos="0.00833334 0 0" quat="0.707107 0 -0.707107 0" type="capsule" contype="0" conaffinity="0" condim="1" solref="0.001" mass="0.000441834" rgba="0.1 0.0533333 0.673333 1" />
                                                  <plugin instance="composite" />
                                                  <body name="B_22" pos="0.0166667 0 0">
                                                    <joint name="J_22" pos="0 0 0" type="ball" group="3" actuatorfrclimited="false" damping="0.1" />
                                                    <geom name="G22" size="0.006 0.00833333" pos="0.00833333 0 0" quat="0.707107 0 -0.707107 0" type="capsule" contype="0" conaffinity="0" condim="1" solref="0.001" mass="0.000441834" rgba="0.1 0.0533333 0.673333 1" />
                                                    <plugin instance="composite" />
                                                    <body name="B_23" pos="0.0166667 0 0">
                                                      <joint name="J_23" pos="0 0 0" type="ball" group="3" actuatorfrclimited="false" damping="0.1" />
                                                      <geom name="G23" size="0.006 0.00833334" pos="0.00833334 0 0" quat="0.707107 0 -0.707107 0" type="capsule" contype="0" conaffinity="0" condim="1" solref="0.001" mass="0.000441834" rgba="0.1 0.0533333 0.673333 1" />
                                                      <plugin instance="composite" />
                                                      <body name="B_24" pos="0.0166667 0 0">
                                                        <joint name="J_24" pos="0 0 0" type="ball" group="3" actuatorfrclimited="false" damping="0.1" />
                                                        <geom name="G24" size="0.006 0.00833333" pos="0.00833333 0 0" quat="0.707107 0 -0.707107 0" type="capsule" contype="0" conaffinity="0" condim="1" solref="0.001" mass="0.000441834" rgba="0.1 0.0533333 0.673333 1" />
                                                        <plugin instance="composite" />
                                                        <body name="B_25" pos="0.0166667 0 0">
                                                          <joint name="J_25" pos="0 0 0" type="ball" group="3" actuatorfrclimited="false" damping="0.1" />
                                                          <geom name="G25" size="0.006 0.00833334" pos="0.00833334 0 0" quat="0.707107 0 -0.707107 0" type="capsule" contype="0" conaffinity="0" condim="1" solref="0.001" mass="0.000441834" rgba="0.1 0.0533333 0.673333 1" />
                                                          <plugin instance="composite" />
                                                          <body name="B_26" pos="0.0166667 0 0">
                                                            <joint name="J_26" pos="0 0 0" type="ball" group="3" actuatorfrclimited="false" damping="0.1" />
                                                            <geom name="G26" size="0.006 0.00833333" pos="0.00833333 0 0" quat="0.707107 0 -0.707107 0" type="capsule" contype="0" conaffinity="0" condim="1" solref="0.001" mass="0.000441834" rgba="0.1 0.0533333 0.673333 1" />
                                                            <plugin instance="composite" />
                                                            <body name="B_27" pos="0.0166667 0 0">
                                                              <joint name="J_27" pos="0 0 0" type="ball" group="3" actuatorfrclimited="false" damping="0.1" />
                                                              <geom name="G27" size="0.006 0.00833334" pos="0.00833334 0 0" quat="0.707107 0 -0.707107 0" type="capsule" contype="0" conaffinity="0" condim="1" solref="0.001" mass="0.000441834" rgba="0.1 0.0533333 0.673333 1" />
                                                              <plugin instance="composite" />
                                                              <body name="B_28" pos="0.0166667 0 0">
                                                                <joint name="J_28" pos="0 0 0" type="ball" group="3" actuatorfrclimited="false" damping="0.1" />
                                                                <geom name="G28" size="0.006 0.00833333" pos="0.00833333 0 0" quat="0.707107 0 -0.707107 0" type="capsule" contype="0" conaffinity="0" condim="1" solref="0.001" mass="0.000441834" rgba="0.1 0.0533333 0.673333 1" />
                                                                <plugin instance="composite" />
                                                                <body name="B_last" pos="0.0166667 0 0">
                                                                  <joint name="J_last" pos="0 0 0" type="ball" group="3" actuatorfrclimited="false" damping="0.1" />
                                                                  <geom name="G29" size="0.006 0.00833334" pos="0.00833334 0 0" quat="0.707107 0 -0.707107 0" type="capsule" contype="0" conaffinity="0" condim="1" solref="0.001" mass="0.000441834" rgba="0.1 0.0533333 0.673333 1" />
                                                                  <site name="S_last" pos="0.0166667 0 0" group="3" />
                                                                  <plugin instance="composite" />
                                                                  <body name="B_last2" pos="0.0166667 0 0">
                                                                    <plugin instance="composite" />
                                                                  </body>
                                                                </body>
                                                              </body>
                                                            </body>
                                                          </body>
                                                        </body>
                                                      </body>
                                                    </body>
                                                  </body>
                                                </body>
                                              </body>
                                            </body>
                                          </body>
                                        </body>
                                      </body>
                                    </body>
                                  </body>
                                </body>
                              </body>
                            </body>
                          </body>
                        </body>
                      </body>
                    </body>
                  </body>
                </body>
              </body>
            </body>
          </body>
        </body>
      </body>
    </body>
  </worldbody>

  <contact>
    <exclude body1="B_first" body2="B_1" />
    <exclude body1="B_1" body2="B_2" />
    <exclude body1="B_2" body2="B_3" />
    <exclude body1="B_3" body2="B_4" />
    <exclude body1="B_4" body2="B_5" />
    <exclude body1="B_5" body2="B_6" />
    <exclude body1="B_6" body2="B_7" />
    <exclude body1="B_7" body2="B_8" />
    <exclude body1="B_8" body2="B_9" />
    <exclude body1="B_9" body2="B_10" />
    <exclude body1="B_10" body2="B_11" />
    <exclude body1="B_11" body2="B_12" />
    <exclude body1="B_12" body2="B_13" />
    <exclude body1="B_13" body2="B_14" />
    <exclude body1="B_14" body2="B_15" />
    <exclude body1="B_15" body2="B_16" />
    <exclude body1="B_16" body2="B_17" />
    <exclude body1="B_17" body2="B_18" />
    <exclude body1="B_18" body2="B_19" />
    <exclude body1="B_19" body2="B_20" />
    <exclude body1="B_20" body2="B_21" />
    <exclude body1="B_21" body2="B_22" />
    <exclude body1="B_22" body2="B_23" />
    <exclude body1="B_23" body2="B_24" />
    <exclude body1="B_24" body2="B_25" />
    <exclude body1="B_25" body2="B_26" />
    <exclude body1="B_26" body2="B_27" />
    <exclude body1="B_27" body2="B_28" />
    <exclude body1="B_28" body2="B_last" />
  </contact>
</mujoco>